Workbook

Sheet Dashboard
A1: מערכת ניהול פרגו – Dashboard
A3: מדד | B3: יעד / הערה | C3: בפועל | E3: 📅 לוח שנה עסקי
A4: מחזור חודשי | B4: 210000 | C4: =SUM('יומן עסקי'!E2:E32) -> 21381.7 | E4: היום | F4: =TODAY() -> 46208
A5: מחזור מצטבר | C5: =C4 -> 21381.7 | E5: תאריך עברי | F5: =IFERROR(VLOOKUP(TODAY(),'לוח שנה עסקי'!$A:$H,3,FALSE),"") -> כ׳ תמוז תשפ״ו
A6: ימים עם נתונים | C6: =COUNT('יומן עסקי'!E2:E32) -> 4 | E6: אירוע קרוב | F6: =IFERROR(INDEX('לוח שנה עסקי'!$D:$D,MATCH(_xludf.MINIFS('לוח שנה עסקי'!$A:$A,'לוח שנה עסקי'!$A:$A,">="&TODAY(),'לוח שנה עסקי'!$D:$D,"<>"),'לוח שנה עסקי'!$A:$A,0)),"אין אירוע קרוב") -> אין אירוע קרוב
A7: ממוצע יומי בפועל | C7: =IF(C6=0,"",C4/C6) -> 5345.425 | E7: נותרו ימים | F7: =IFERROR(_xludf.MINIFS('לוח שנה עסקי'!$A:$A,'לוח שנה עסקי'!$A:$A,">="&TODAY(),'לוח שנה עסקי'!$D:$D,"<>")-TODAY(),"")
A8: קצב חודשי משוער | C8: =IF(C6=0,"",C7*30) -> 160362.75 | E8: משימה | F8: =IFERROR(INDEX('לוח שנה עסקי'!$F:$F,MATCH(_xludf.MINIFS('לוח שנה עסקי'!$A:$A,'לוח שנה עסקי'!$A:$A,">="&TODAY(),'לוח שנה עסקי'!$D:$D,"<>"),'לוח שנה עסקי'!$A:$A,0)),"")
A9: מספר עסקאות | C9: =SUM('יומן עסקי'!F2:F32) -> 166 | E9: אחראי | F9: =IFERROR(INDEX('לוח שנה עסקי'!$G:$G,MATCH(_xludf.MINIFS('לוח שנה עסקי'!$A:$A,'לוח שנה עסקי'!$A:$A,">="&TODAY(),'לוח שנה עסקי'!$D:$D,"<>"),'לוח שנה עסקי'!$A:$A,0)),"")
A10: ממוצע הזמנה | B10: 90 | C10: =IF(C9=0,"",C4/C9) -> 128.80542 | E10: סטטוס | F10: =IFERROR(INDEX('לוח שנה עסקי'!$H:$H,MATCH(_xludf.MINIFS('לוח שנה עסקי'!$A:$A,'לוח שנה עסקי'!$A:$A,">="&TODAY(),'לוח שנה עסקי'!$D:$D,"<>"),'לוח שנה עסקי'!$A:$A,0)),"")
A11: משלוחים | C11: =SUM('יומן עסקי'!H2:H32) -> 21
A12: איסוף עצמי | C12: =SUM('יומן עסקי'!I2:I32) -> 13
A13: ישיבה במקום | C13: =SUM('יומן עסקי'!J2:J32) -> 147 | E13: משימות ושיווק
A14: יתרת בנק | C14: 0 | E14: משימות בתהליך | F14: =COUNTIF(משימות!E2:E100,"בתהליך") -> 1
A15: מזומן בקופה | C15: 0 | E15: משימות תקועות | F15: =COUNTIF(משימות!E2:E100,"תקוע") -> 0
E16: לקוחות פוטנציאליים | F16: =COUNTA('לקוחות פוטנציאליים'!B2:B101) -> 0
A17: בקרת אמצעי תשלום והפקדות | E17: הזמנות ראשונות | F17: =COUNTIF('לקוחות פוטנציאליים'!K2:K101,"4-הזמנה ראשונה") -> 0
A18: מדד | B18: הערה | C18: בפועל | E18: לקוחות קבועים | F18: =COUNTIF('לקוחות פוטנציאליים'!K2:K101,"5-לקוח קבוע") -> 0
A19: מזומן שהתקבל | C19: =SUM('יומן עסקי'!K2:K32) -> 0
A20: אשראי / קופה | C20: =SUM('יומן עסקי'!L2:L32) -> 0
A21: תן ביס / סיבוס | C21: =SUM('יומן עסקי'!M2:M32) -> 0
A22: וולט / משלוחה | C22: =SUM('יומן עסקי'!N2:N32) -> 0
A23: אחר | C23: =SUM('יומן עסקי'!O2:O32) -> 0
A24: סה״כ אמצעי תשלום | B24: צריך להיות שווה למחזור | C24: =SUM('יומן עסקי'!P2:P32) -> 0
A25: הפרש מול מחזור | B25: חריגה דורשת בדיקה | C25: =SUM('יומן עסקי'!Q2:Q32) -> 0
A26: מזומן שהופקד לבנק | C26: =SUM('יומן עסקי'!R2:R32) -> 0
A27: מזומן שצריך להפקיד | B27: מזומן פחות הפקדות | C27: =SUM('יומן עסקי'!S2:S32) -> 0

Sheet יומן עסקי
A1: תאריך לועזי | B1: יום | C1: תאריך עברי | D1: אירוע / תקופה | E1: מחזור | F1: מספר עסקאות | G1: ממוצע הזמנה | H1: משלוחים | I1: איסוף עצמי | J1: ישיבה במקום | K1: מזומן שהתקבל | L1: אשראי / קופה | M1: תן ביס / סיבוס | N1: וולט / משלוחה | O1: אחר | P1: סה״כ אמצעי תשלום | Q1: הפרש מול מחזור | R1: מזומן שהופקד לבנק | S1: מזומן שצריך להפקיד | T1: הפרש הפקדה | U1: הערות
A2: 46204 | B2: רביעי | C2: ט״ז תמוז תשפ״ו | E2: 10627.08 | F2: 73 | G2: =IF(OR(E2="",F2=""),"",E2/F2) -> 145.57644 | H2: 8 | I2: 9 | J2: 58 | P2: =IF(COUNTA(K2:O2)=0,"",SUM(K2:O2)) | Q2: =IF(OR(E2="",P2=""),"",P2-E2) | S2: =IF(K2="","",K2-R2) | T2: =IF(OR(K2="",R2=""),"",R2-K2)
A3: 46205 | B3: חמישי | C3: י״ז תמוז תשפ״ו | D3: בין המצרים | E3: 7628.72 | F3: 67 | G3: =IF(OR(E3="",F3=""),"",E3/F3) -> 113.86149 | H3: 11 | I3: 2 | J3: 54 | P3: =IF(COUNTA(K3:O3)=0,"",SUM(K3:O3)) | Q3: =IF(OR(E3="",P3=""),"",P3-E3) | S3: =IF(K3="","",K3-R3) | T3: =IF(OR(K3="",R3=""),"",R3-K3) | U3: צום יז' בתמוז
A4: 46206 | B4: שישי | C4: י״ח תמוז תשפ״ו | D4: בין המצרים | E4: 1600.1 | F4: 12 | G4: =IF(OR(E4="",F4=""),"",E4/F4) -> 133.34167 | I4: 1 | J4: 16 | P4: =IF(COUNTA(K4:O4)=0,"",SUM(K4:O4)) | Q4: =IF(OR(E4="",P4=""),"",P4-E4) | S4: =IF(K4="","",K4-R4) | T4: =IF(OR(K4="",R4=""),"",R4-K4) | U4: יום שישי
A5: 46207 | B5: שבת | C5: י״ט תמוז תשפ״ו | D5: בין המצרים | E5: 1525.8 | F5: 14 | G5: =IF(OR(E5="",F5=""),"",E5/F5) -> 108.98571 | H5: 2 | I5: 1 | J5: 19 | P5: =IF(COUNTA(K5:O5)=0,"",SUM(K5:O5)) | Q5: =IF(OR(E5="",P5=""),"",P5-E5) | S5: =IF(K5="","",K5-R5) | T5: =IF(OR(K5="",R5=""),"",R5-K5) | U5: מוצא"ש
A6: 46208 | B6: ראשון | C6: כ׳ תמוז תשפ״ו | D6: בין המצרים | G6: =IF(OR(E6="",F6=""),"",E6/F6) | P6: =IF(COUNTA(K6:O6)=0,"",SUM(K6:O6)) | Q6: =IF(OR(E6="",P6=""),"",P6-E6) | S6: =IF(K6="","",K6-R6) | T6: =IF(OR(K6="",R6=""),"",R6-K6)
A7: 46209 | B7: שני | C7: כ״א תמוז תשפ״ו | D7: בין המצרים | G7: =IF(OR(E7="",F7=""),"",E7/F7) | P7: =IF(COUNTA(K7:O7)=0,"",SUM(K7:O7)) | Q7: =IF(OR(E7="",P7=""),"",P7-E7) | S7: =IF(K7="","",K7-R7) | T7: =IF(OR(K7="",R7=""),"",R7-K7)
A8: 46210 | B8: שלישי | C8: כ״ב תמוז תשפ״ו | D8: בין המצרים | G8: =IF(OR(E8="",F8=""),"",E8/F8) | P8: =IF(COUNTA(K8:O8)=0,"",SUM(K8:O8)) | Q8: =IF(OR(E8="",P8=""),"",P8-E8) | S8: =IF(K8="","",K8-R8) | T8: =IF(OR(K8="",R8=""),"",R8-K8)
A9: 46211 | B9: רביעי | C9: כ״ג תמוז תשפ״ו | D9: בין המצרים | G9: =IF(OR(E9="",F9=""),"",E9/F9) | P9: =IF(COUNTA(K9:O9)=0,"",SUM(K9:O9)) | Q9: =IF(OR(E9="",P9=""),"",P9-E9) | S9: =IF(K9="","",K9-R9) | T9: =IF(OR(K9="",R9=""),"",R9-K9)
A10: 46212 | B10: חמישי | C10: כ״ד תמוז תשפ״ו | D10: בין המצרים | G10: =IF(OR(E10="",F10=""),"",E10/F10) | P10: =IF(COUNTA(K10:O10)=0,"",SUM(K10:O10)) | Q10: =IF(OR(E10="",P10=""),"",P10-E10) | S10: =IF(K10="","",K10-R10) | T10: =IF(OR(K10="",R10=""),"",R10-K10)
A11: 46213 | B11: שישי | C11: כ״ה תמוז תשפ״ו | D11: בין המצרים | G11: =IF(OR(E11="",F11=""),"",E11/F11) | P11: =IF(COUNTA(K11:O11)=0,"",SUM(K11:O11)) | Q11: =IF(OR(E11="",P11=""),"",P11-E11) | S11: =IF(K11="","",K11-R11) | T11: =IF(OR(K11="",R11=""),"",R11-K11)
A12: 46214 | B12: שבת | C12: כ״ו תמוז תשפ״ו | D12: בין המצרים | G12: =IF(OR(E12="",F12=""),"",E12/F12) | P12: =IF(COUNTA(K12:O12)=0,"",SUM(K12:O12)) | Q12: =IF(OR(E12="",P12=""),"",P12-E12) | S12: =IF(K12="","",K12-R12) | T12: =IF(OR(K12="",R12=""),"",R12-K12)
A13: 46215 | B13: ראשון | C13: כ״ז תמוז תשפ״ו | D13: בין המצרים | G13: =IF(OR(E13="",F13=""),"",E13/F13) | P13: =IF(COUNTA(K13:O13)=0,"",SUM(K13:O13)) | Q13: =IF(OR(E13="",P13=""),"",P13-E13) | S13: =IF(K13="","",K13-R13) | T13: =IF(OR(K13="",R13=""),"",R13-K13)
A14: 46216 | B14: שני | C14: כ״ח תמוז תשפ״ו | D14: בין המצרים | G14: =IF(OR(E14="",F14=""),"",E14/F14) | P14: =IF(COUNTA(K14:O14)=0,"",SUM(K14:O14)) | Q14: =IF(OR(E14="",P14=""),"",P14-E14) | S14: =IF(K14="","",K14-R14) | T14: =IF(OR(K14="",R14=""),"",R14-K14)
A15: 46217 | B15: שלישי | C15: כ״ט תמוז תשפ״ו | D15: בין המצרים | G15: =IF(OR(E15="",F15=""),"",E15/F15) | P15: =IF(COUNTA(K15:O15)=0,"",SUM(K15:O15)) | Q15: =IF(OR(E15="",P15=""),"",P15-E15) | S15: =IF(K15="","",K15-R15) | T15: =IF(OR(K15="",R15=""),"",R15-K15)
A16: 46218 | B16: רביעי | C16: א׳ אב תשפ״ו | D16: תשעת הימים | G16: =IF(OR(E16="",F16=""),"",E16/F16) | P16: =IF(COUNTA(K16:O16)=0,"",SUM(K16:O16)) | Q16: =IF(OR(E16="",P16=""),"",P16-E16) | S16: =IF(K16="","",K16-R16) | T16: =IF(OR(K16="",R16=""),"",R16-K16)
A17: 46219 | B17: חמישי | C17: ב׳ אב תשפ״ו | D17: תשעת הימים | G17: =IF(OR(E17="",F17=""),"",E17/F17) | P17: =IF(COUNTA(K17:O17)=0,"",SUM(K17:O17)) | Q17: =IF(OR(E17="",P17=""),"",P17-E17) | S17: =IF(K17="","",K17-R17) | T17: =IF(OR(K17="",R17=""),"",R17-K17)
... A26: 46228 | B26: שבת | C26: י״א אב תשפ״ו | D26: מוצאי שבת | G26: =IF(OR(E26="",F26=""),"",E26/F26) | P26: =IF(COUNTA(K26:O26)=0,"",SUM(K26:O26)) | Q26: =IF(OR(E26="",P26=""),"",P26-E26) | S26: =IF(K26="","",K26-R26) | T26: =IF(OR(K26="",R26=""),"",R26-K26)
A27: 46229 | B27: ראשון | C27: י״ב אב תשפ״ו | G27: =IF(OR(E27="",F27=""),"",E27/F27) | P27: =IF(COUNTA(K27:O27)=0,"",SUM(K27:O27)) | Q27: =IF(OR(E27="",P27=""),"",P27-E27) | S27: =IF(K27="","",K27-R27) | T27: =IF(OR(K27="",R27=""),"",R27-K27)
A28: 46230 | B28: שני | C28: י״ג אב תשפ״ו | G28: =IF(OR(E28="",F28=""),"",E28/F28) | P28: =IF(COUNTA(K28:O28)=0,"",SUM(K28:O28)) | Q28: =IF(OR(E28="",P28=""),"",P28-E28) | S28: =IF(K28="","",K28-R28) | T28: =IF(OR(K28="",R28=""),"",R28-K28)
A29: 46231 | B29: שלישי | C29: י״ד אב תשפ״ו | G29: =IF(OR(E29="",F29=""),"",E29/F29) | P29: =IF(COUNTA(K29:O29)=0,"",SUM(K29:O29)) | Q29: =IF(OR(E29="",P29=""),"",P29-E29) | S29: =IF(K29="","",K29-R29) | T29: =IF(OR(K29="",R29=""),"",R29-K29)
A30: 46232 | B30: רביעי | C30: ט״ו אב תשפ״ו | D30: ט״ו באב | G30: =IF(OR(E30="",F30=""),"",E30/F30) | P30: =IF(COUNTA(K30:O30)=0,"",SUM(K30:O30)) | Q30: =IF(OR(E30="",P30=""),"",P30-E30) | S30: =IF(K30="","",K30-R30) | T30: =IF(OR(K30="",R30=""),"",R30-K30)
A31: 46233 | B31: חמישי | C31: ט״ז אב תשפ״ו | G31: =IF(OR(E31="",F31=""),"",E31/F31) | P31: =IF(COUNTA(K31:O31)=0,"",SUM(K31:O31)) | Q31: =IF(OR(E31="",P31=""),"",P31-E31) | S31: =IF(K31="","",K31-R31) | T31: =IF(OR(K31="",R31=""),"",R31-K31)
A32: 46234 | B32: שישי | C32: י״ז אב תשפ״ו | D32: יום שישי | G32: =IF(OR(E32="",F32=""),"",E32/F32) | P32: =IF(COUNTA(K32:O32)=0,"",SUM(K32:O32)) | Q32: =IF(OR(E32="",P32=""),"",P32-E32) | S32: =IF(K32="","",K32-R32) | T32: =IF(OR(K32="",R32=""),"",R32-K32)

Sheet לוח שנה עסקי
A1: תאריך לועזי | B1: יום | C1: תאריך עברי | D1: אירוע / תקופה | E1: חשיבות | F1: משימה עסקית מומלצת | G1: אחראי | H1: בוצע
A2: 46204 | B2: רביעי | C2: ט״ז תמוז תשפ״ו
A3: 46205 | B3: חמישי | C3: י״ז תמוז תשפ״ו | D3: בין המצרים | E3: גבוהה | F3: דגש חלבי ודגים; לפרסם סלמון | G3: מרדכי
A4: 46206 | B4: שישי | C4: י״ח תמוז תשפ״ו | D4: בין המצרים | E4: גבוהה | F4: דגש חלבי ודגים; לפרסם סלמון | G4: מרדכי
A5: 46207 | B5: שבת | C5: י״ט תמוז תשפ״ו | D5: בין המצרים | E5: גבוהה | F5: דגש חלבי ודגים; לפרסם סלמון | G5: מרדכי
A6: 46208 | B6: ראשון | C6: כ׳ תמוז תשפ״ו | D6: בין המצרים | E6: גבוהה | F6: דגש חלבי ודגים; לפרסם סלמון | G6: מרדכי
A7: 46209 | B7: שני | C7: כ״א תמוז תשפ״ו | D7: בין המצרים | E7: גבוהה | F7: דגש חלבי ודגים; לפרסם סלמון | G7: מרדכי
A8: 46210 | B8: שלישי | C8: כ״ב תמוז תשפ״ו | D8: בין המצרים | E8: גבוהה | F8: דגש חלבי ודגים; לפרסם סלמון | G8: מרדכי
A9: 46211 | B9: רביעי | C9: כ״ג תמוז תשפ״ו | D9: בין המצרים | E9: גבוהה | F9: דגש חלבי ודגים; לפרסם סלמון | G9: מרדכי
A10: 46212 | B10: חמישי | C10: כ״ד תמוז תשפ״ו | D10: בין המצרים | E10: גבוהה | F10: דגש חלבי ודגים; לפרסם סלמון | G10: מרדכי
A11: 46213 | B11: שישי | C11: כ״ה תמוז תשפ״ו | D11: בין המצרים | E11: גבוהה | F11: דגש חלבי ודגים; לפרסם סלמון | G11: מרדכי
A12: 46214 | B12: שבת | C12: כ״ו תמוז תשפ״ו | D12: בין המצרים | E12: גבוהה | F12: דגש חלבי ודגים; לפרסם סלמון | G12: מרדכי
A13: 46215 | B13: ראשון | C13: כ״ז תמוז תשפ״ו | D13: בין המצרים | E13: גבוהה | F13: דגש חלבי ודגים; לפרסם סלמון | G13: מרדכי
A14: 46216 | B14: שני | C14: כ״ח תמוז תשפ״ו | D14: בין המצרים | E14: גבוהה | F14: דגש חלבי ודגים; לפרסם סלמון | G14: מרדכי
... A26: 46228 | B26: שבת | C26: י״א אב תשפ״ו | D26: מוצאי שבת | E26: בינונית | F26: קמפיין סעודה רביעית / סלמון | G26: אנה + מרדכי
A27: 46229 | B27: ראשון | C27: י״ב אב תשפ״ו
A28: 46230 | B28: שני | C28: י״ג אב תשפ״ו
A29: 46231 | B29: שלישי | C29: י״ד אב תשפ״ו
A30: 46232 | B30: רביעי | C30: ט״ו אב תשפ״ו | D30: ט״ו באב | E30: גבוהה | F30: קמפיין זוגות / ערב חלבי בוטיק | G30: מרדכי
A31: 46233 | B31: חמישי | C31: ט״ז אב תשפ״ו
A32: 46234 | B32: שישי | C32: י״ז אב תשפ״ו | D32: יום שישי | E32: בינונית | F32: קמפיין שבת / קציצות דגים / סלטים | G32: אנה + מרדכי
A33: 46235 | B33: שבת | C33: י״ח אב תשפ״ו | D33: מוצאי שבת | E33: בינונית | F33: קמפיין סעודה רביעית / סלמון | G33: אנה + מרדכי
A34: 46236 | B34: ראשון | C34: י״ט אב תשפ״ו
A35: 46237 | B35: שני | C35: כ׳ אב תשפ״ו
A36: 46238 | B36: שלישי | C36: כ״א אב תשפ״ו
A37: 46239 | B37: רביעי | C37: כ״ב אב תשפ״ו
A38: 46240 | B38: חמישי | C38: כ״ג אב תשפ״ו
A39: 46241 | B39: שישי | C39: כ״ד אב תשפ״ו | D39: יום שישי | E39: בינונית | F39: קמפיין שבת / קציצות דגים / סלטים | G39: אנה + מרדכי
A40: 46242 | B40: שבת | C40: כ״ה אב תשפ״ו | D40: מוצאי שבת | E40: בינונית | F40: קמפיין סעודה רביעית / סלמון | G40: אנה + מרדכי
A41: 46243 | B41: ראשון | C41: כ״ו אב תשפ״ו
A42: 46244 | B42: שני | C42: כ״ז אב תשפ״ו
A43: 46245 | B43: שלישי | C43: כ״ח אב תשפ״ו
A44: 46246 | B44: רביעי | C44: כ״ט אב תשפ״ו
A45: 46247 | B45: חמישי | C45: ל׳ אב תשפ״ו
A46: 46248 | B46: שישי | C46: א׳ אלול תשפ״ו | D46: יום שישי | E46: בינונית | F46: קמפיין שבת / קציצות דגים / סלטים | G46: אנה + מרדכי
A47: 46249 | B47: שבת | C47: ב׳ אלול תשפ״ו | D47: מוצאי שבת | E47: בינונית | F47: קמפיין סעודה רביעית / סלמון | G47: אנה + מרדכי
A48: 46250 | B48: ראשון | C48: ג׳ אלול תשפ״ו
A49: 46251 | B49: שני | C49: ד׳ אלול תשפ״ו
A50: 46252 | B50: שלישי | C50: ה׳ אלול תשפ״ו
A51: 46253 | B51: רביעי | C51: ו׳ אלול תשפ״ו
...

Sheet משימות
A1: משימה | B1: תחום | C1: אחראי | D1: תאריך יעד | E1: סטטוס | F1: הערות
A2: מסכי כניסה | B2: שיווק | C2: מרדכי | E2: מתוכנן
A3: טאבלטים למלצרים | B3: שירות | C3: מרדכי | E3: מתוכנן
A4: צילום מנות | B4: שיווק | C4: אנה | E4: מתוכנן
A5: פנייה לבתי ספר ועסקים | B5: מכירות | C5: מרדכי | E5: מתוכנן
A6: בדיקת כשרות | B6: אסטרטגיה | C6: אנה + מרדכי | E6: מתוכנן
A7: שדרוג הגשת מנות | B7: תפריט | C7: אנה + מרדכי | E7: מתוכנן
A8: קמפיין סלמון בין המצרים | B8: שיווק | C8: מרדכי | E8: בתהליך
A9: קמפיין קציצות דגים לשישי | B9: שיווק | C9: אנה + מרדכי | E9: מתוכנן

Sheet לקוחות פוטנציאליים
A1: מס׳ | B1: שם העסק / מוסד | C1: קטגוריה | D1: איש קשר | E1: תפקיד | F1: טלפון | G1: כתובת | H1: מנת טעימה | I1: מכתב אישי | J1: תאריך מסירה | K1: שלב במשפך | L1: שיחת מעקב | M1: הזמנה ראשונה | N1: הערות
A2: 1
A3: 2
A4: 3
A5: 4
A6: 5
A7: 6
A8: 7
A9: 8
A10: 9
A11: 10
A12: 11
A13: 12
... A101: 100

Sheet תזרים
A1: נתון | B1: סכום
A2: יתרת בנק | B2: 100000
A3: מזומן בקופה | B3: 7000
A4: תשלומים פתוחים לספקים
A5: הערות תזרים
A7: מזומן שהתקבל החודש | B7: =SUM('יומן עסקי'!K2:K32) -> 0
A8: הופקד לבנק | B8: =SUM('יומן עסקי'!R2:R32) -> 0
A9: צריך להפקיד | B9: =SUM('יומן עסקי'!S2:S32) -> 0
A10: הפרש מול מחזור | B10: =SUM('יומן עסקי'!Q2:Q32) -> 0
A11: סה״כ אמצעי תשלום | B11: =SUM('יומן עסקי'!P2:P32) -> 0
A12: מחזור לפי יומן | B12: =SUM('יומן עסקי'!E2:E32) -> 21381.7
A13: בדיקת התאמה | B13: =B11-B12 -> -21381.7

Sheet גרפים
A1: תאריך | B1: מחזור
A2: ='יומן עסקי'!A2 -> 46204 | B2: =IF('יומן עסקי'!E2="",NA(),'יומן עסקי'!E2) -> 10627.08
A3: ='יומן עסקי'!A3 -> 46205 | B3: =IF('יומן עסקי'!E3="",NA(),'יומן עסקי'!E3) -> 7628.72
A4: ='יומן עסקי'!A4 -> 46206 | B4: =IF('יומן עסקי'!E4="",NA(),'יומן עסקי'!E4) -> 1600.1
A5: ='יומן עסקי'!A5 -> 46207 | B5: =IF('יומן עסקי'!E5="",NA(),'יומן עסקי'!E5) -> 1525.8
A6: ='יומן עסקי'!A6 -> 46208 | B6: =IF('יומן עסקי'!E6="",NA(),'יומן עסקי'!E6) -> #N/A
A7: ='יומן עסקי'!A7 -> 46209 | B7: =IF('יומן עסקי'!E7="",NA(),'יומן עסקי'!E7) -> #N/A
A8: ='יומן עסקי'!A8 -> 46210 | B8: =IF('יומן עסקי'!E8="",NA(),'יומן עסקי'!E8) -> #N/A
A9: ='יומן עסקי'!A9 -> 46211 | B9: =IF('יומן עסקי'!E9="",NA(),'יומן עסקי'!E9) -> #N/A
A10: ='יומן עסקי'!A10 -> 46212 | B10: =IF('יומן עסקי'!E10="",NA(),'יומן עסקי'!E10) -> #N/A
A11: ='יומן עסקי'!A11 -> 46213 | B11: =IF('יומן עסקי'!E11="",NA(),'יומן עסקי'!E11) -> #N/A
A12: ='יומן עסקי'!A12 -> 46214 | B12: =IF('יומן עסקי'!E12="",NA(),'יומן עסקי'!E12) -> #N/A
A13: ='יומן עסקי'!A13 -> 46215 | B13: =IF('יומן עסקי'!E13="",NA(),'יומן עסקי'!E13) -> #N/A
... A32: ='יומן עסקי'!A32 -> 46234 | B32: =IF('יומן עסקי'!E32="",NA(),'יומן עסקי'!E32) -> #N/A
